File: MaterialsAutomated2-CpPhononAnalysis/input.dat
[Header]
TITLE,1-26-2018-MK167-Ba2CaWO6-o2-ldfz-hc-.dat
BYAPP,HeatCapacity,3.9.6,1.7
INFO,14.2,MASS:Sample Mass (mg)
INFO,.2,MASSERR:Sample Mass Error (mg)
INFO,594.57,MOLWGHT:Formula Weight (g/mole)
INFO,10,ATOMS:Atoms per Formula Unit
INFO,PPMS Heat Capacity Option 3.9.6 Build 3,APPNAME
DATATYPE,TIME,1
DATATYPE,COMMENT,2
STARTUPAXIS, X, 8, LINEAR, AUTO
STARTUPAXIS, Y1, 10, LINEAR, AUTO
[Data]
Time Stamp (Seconds),Comment (),System Status (Code),Puck Temp (Kelvin),System Temp (Kelvin),Field (Oersted),Pressure (Torr),Sample Temp (Kelvin),Temp Rise (Kelvin),Samp HC (J/mole-K),Samp HC Err (J/mole-K),Addenda HC (uJ/K),Addenda HC Err (uJ/K),Total HC (uJ/K),Total HC Err (uJ/K),Fit Deviation (ChiSquare),Time Const tau1 (seconds),Time Const tau2 (seconds),Sample Coupling (Percent),Debye Temp (Kelvin),Debye Temp Err (Kelvin),Cal Correction (Factor),Therm Resist (Ohms),Htr Resist (Ohms),Puck Resist (Ohms),Wire Cond (W/K),Meas Time (seconds),Temp Squared (K^2),Samp HC/Temp (J/mole-K/K),Addenda Offset HC (uJ/K)
33754794.47,CALFILE: C:\QdPpms\HEATCA~1\TempCal\Standard\Puck1074.cal|Addenda #6 measured on 1/26/2018 from 1.9949 to 300.34 K
33754794.84,,5905,2.00061,1.9986,0.127,9.3E-6,2.0008239,0.038349955,0.0038811068,6.81E-5,0.19017915,0.0006144,0.28287087,0.0007505,13.022388,0.16395623,,,342.32432,2.795,1,,,,1.7252828E-6,0.50624635,4.0032961,0.0019397544,0
33754813.11,,5905,2.00077,1.9986,0.127,9.4E-6,2.0005963,0.037841725,0.0038895071,6.052E-5,0.19015011,0.0006142,0.28304245,0,4.9818576,0.16418455,,,342.03879,2.36,1,,,,1.7239287E-6,0.4918687,4.0023855,0.0019441739,0
33754830.81,,5905,2.00051,1.9987,0.127,9.3E-6,2.0002811,0.037874591,0.0038660042,6.679E-5,0.19007936,0.0006137,0.28241039,0.0006903,11.51469,0.16396133,,,342.67652,2.746,1,,,,1.7224207E-6,0.49255365,4.0011246,0.0019327304,0
33755116.33,Error: Warning:  Measured time constant less than time constant calculated from addenda table.  Changing time constant to addenda table value
33755157.28,,5905,4.21724,4.2521,0.127,9.4E-6,4.2030369,0.075199498,0.027922644,0.0004628,1.4168109,0.002617,2.083682,0.005206,5.0905024,0.49736442,,,372.49896,2.831,1,,,,4.1894472E-6,1.4420775,17.665519,0.0066434448,0
33755178.19,,5905,4.21806,4.253,0.127,9.4E-6,4.2021643,0.076441745,0.028195372,0.0004615,1.415885,0.002616,2.0892696,0.00497,1.3612753,0.50118335,,,371.21695,2.772,1,,,,4.1686731E-6,1.4920932,17.658185,0.0067097262,0
33755198.98,,5905,4.21872,4.2569,0.127,9.3E-6,4.2034806,0.07709662,0.029538115,0.0004858,1.417367,0.002617,2.1228201,0.005387,4.4958788,0.52104117,,,365.61908,2.749,1,,,,4.0741888E-6,1.50355,17.669249,0.0070270612,0
33755480.78,Error: Warning:  Measured time constant less than time constant calculated from addenda table.  Changing time constant to addenda table value
33755528.94,,5905,6.43761,6.4941,0.127,9.4E-6,6.4026067,0.11596634,0.10444587,0.001582,4.472089,0.006326,6.9665494,0.01241,2.703407,0.98736443,,,365.54477,2.399,1,,,,7.0557022E-6,2.9629283,40.993373,0.016313022,0
33755907.83,,5905,8.65982,8.7254,0.127,9.4E-6,8.608805,0.16053199,0.28142583,0.004023,9.6277911,0.01195,16.34903,0.01645,11.511644,1.592993,0.0080299882,97.946075,353.21212,1.952,1,,,,1.0299649E-5,4.8855454,74.111524,0.032690464,0
33756532.64,,5905,10.9008,10.9396,0.127,9.4E-6,10.817758,0.20047193,0.70609223,0.01007,17.031423,0.02336,33.894886,0.03827,11.529927,2.4893534,0.014829661,97.645131,326.63616,1.786,1,,,,1.3697711E-5,7.4602958,117.02388,0.065271588,0
33756961.95,,5905,13.1196,13.1535,0.127,9.4E-6,13.013859,0.24455272,1.5264441,0.02172,26.656812,0.0364,63.112581,0.0733,5.0346791,3.7460534,0.021429289,97.673073,303.89703,1.636,1,,,,1.6982451E-5,11.213762,169.36052,0.11729374,0
33757433.44,,5905,15.3434,15.3816,0.127,9.4E-6,15.220316,0.28947121,2.8615351,0.0407,38.641731,0.05229,106.98322,0.1361,6.2717532,5.3300092,0.030258227,97.550143,288.24775,1.55,1,,,,2.0278752E-5,16.127367,231.65801,0.18800761,0
33757895.95,,5905,17.5692,17.5966,0.127,9.4E-6,17.40803,0.28280478,4.7177786,0.06687,52.92741,0.07352,165.6012,0.1789,18.365721,7.218702,0.045037914,97.136002,279.03941,1.465,1,,,,2.3255695E-5,15.927921,303.03952,0.27101162,0
33758399.95,,5905,19.7915,19.8322,0.127,9.4E-6,19.621147,0.33367767,7.1005226,0.1006,69.248152,0.1074,238.82855,0.2599,26.423131,9.3505494,0.055485891,97.115897,274.32373,1.442,1,,,,2.5926404E-5,21.648041,384.9894,0.36188112,0
33758946.39,,5905,22.0164,22.0552,0.127,9.4E-6,21.839513,0.37979614,9.9157603,0.1405,87.568363,0.1499,324.38454,0.3561,57.250863,11.492951,0.065450843,97.103593,272.87367,1.444,1,,,,2.8675963E-5,27.765052,476.96434,0.45402845,0
33759539.77,,5905,24.2431,24.2756,0.127,9.4E-6,24.054675,0.42768383,13.061077,0.1848,107.56678,0.1907,419.50194,0.4316,15.026796,13.624469,0.074836008,97.10908,273.64033,1.458,1,,,,3.1299997E-5,34.221522,578.62738,0.54297457,0
33760176.17,,5905,26.4703,26.506,0.127,9.4E-6,26.276074,0.47506691,16.399933,0.2319,128.962,0.2335,520.63843,0.5007,15.9162,15.784625,0.086675871,97.040303,276.27289,1.489,1,,,,3.3556445E-5,40.700165,690.43206,0.62413941,0
33760857.59,,5905,28.6938,28.7288,0.127,9.3E-6,28.495353,0.51995904,19.927369,0.2818,151.57046,0.279,627.49194,0.597,3.9586234,17.846666,0.097715882,96.996335,279.70303,1.538,1,,,,3.5790015E-5,47.017155,811.98514,0.69931994,0
33761605.73,,5905,30.9151,30.9709,0.127,9.3E-6,30.722974,0.56657907,23.551578,0.3333,175.96565,0.3329,738.44342,0.7754,0.90694076,20.001595,0.11192044,96.900191,283.91879,1.612,1,,,,3.760839E-5,53.289705,943.9011,0.76657873,0
33762392.03,,5905,33.1434,33.1981,0.127,9.3E-6,32.952009,0.60920416,27.222654,0.3851,201.95954,0.3906,852.11292,0.8576,0.52978051,21.952668,0.12411556,96.855629,288.63185,1.674,1,,,,3.9553761E-5,59.04262,1085.8349,0.82613035,0
33763276.56,,5905,35.3733,35.4207,0.127,9.3E-6,35.176819,0.65217628,30.890066,0.4372,229.36704,0.4481,967.10849,1.022,0.26660388,23.75833,0.13682544,96.798231,293.6893,1.756,1,,,,4.1494209E-5,64.751399,1237.4086,0.87813699,0
33764200.97,,5905,37.6022,37.6465,0.127,9.3E-6,37.405069,0.69323376,34.434295,0.4868,257.90656,0.4924,1080.2942,0.9971,0.39906867,25.29011,0.14574589,96.811134,299.35752,1.817,1,,,,4.3536292E-5,69.985239,1399.1392,0.92057832,0
33765203.52,,5905,39.8294,39.8606,0.127,9.3E-6,39.62825,0.73673921,37.733768,0.5337,287.83911,0.5343,1189.0274,1.162,1.0715706,26.586496,0.15318093,96.843256,305.77003,1.911,1,,,,4.5565355E-5,75.320103,1570.3982,0.95219365,0
33766245.13,,5905,42.0542,42.0801,0.127,9.4E-6,41.85189,0.78106287,41.114998,0.5816,319.43357,0.5823,1301.3751,1.292,1.6537713,28.055135,0.16407585,96.826642,311.77988,2.002,1,,,,4.7257056E-5,80.269575,1751.5807,0.98239286,0
33767327.67,,5905,44.2803,44.3097,0.127,9.4E-6,44.074982,0.82376592,44.537222,0.6299,352.95529,0.6308,1416.6291,1.361,0.7173286,29.544879,0.17829923,96.758904,317.50009,2.087,1,,,,4.8859465E-5,84.854778,1942.604,1.0104876,0
33768444.72,,5905,46.5058,46.5372,0.127,9.4E-6,46.304786,0.86505913,47.84125,0.6769,388.73015,0.6805,1531.3134,1.536,1.7054085,30.834103,0.18903754,96.749469,323.43721,2.19,1,,,,5.0597755E-5,89.159702,2144.1332,1.0331815,0
33769592.75,,5905,48.7306,48.7693,0.127,9.4E-6,48.529365,0.90880887,51.206647,0.724,426.38734,0.7243,1649.3458,1.519,0.28682466,32.372206,0.20951991,96.610084,328.94547,2.27,1,,,,5.193886E-5,93.537847,2355.0992,1.0551683,0
33770771.91,,5905,50.9537,50.9973,0.127,9.3E-6,50.752118,0.95111863,54.452311,0.7696,465.83607,0.7528,1766.3101,1.531,0.25387947,33.778636,0.22570724,96.546706,334.56288,2.358,1,,,,5.3311589E-5,97.483706,2575.7775,1.0729072,0
33771969.48,,5905,53.1778,53.2256,0.127,9.3E-6,52.969857,0.99457655,57.745323,0.8162,507.06968,0.7722,1886.19,1.628,0.20868443,35.361649,0.24953647,96.398581,339.78186,2.457,1,,,,5.4413059E-5,101.30285,2805.8058,1.0901544,0
33773218.3,,5905,55.4044,55.4385,0.127,9.4E-6,55.195729,1.032731,60.574704,0.856,550.19004,0.7918,1996.884,1.674,0.26829089,36.179193,0.25520756,96.457665,346.08957,2.555,1,,,,5.6265854E-5,104.9456,3046.5685,1.0974527,0
33774465.58,,5905,57.6303,57.6781,0.127,9.3E-6,57.419829,1.0786137,63.858209,0.9026,594.90594,0.8093,2120.0192,1.818,0.25971952,37.923218,0.28637749,96.251689,350.88842,2.665,1,,,,5.7038325E-5,108.61639,3297.0368,1.1121282,0
33775763.67,,5905,59.8569,59.893,0.127,9.3E-6,59.649548,1.1188066,66.48607,0.9398,642.00309,0.8289,2229.877,1.896,0.17728935,38.788358,0.29467196,96.29009,357.25252,2.77,1,,,,5.8620209E-5,111.88471,3558.0685,1.1146115,0
33777045.03,,5905,62.0698,62.1164,0.127,9.3E-6,61.856499,1.1584682,69.59691,0.9831,691.67059,0.8559,2353.8401,1.785,0.42674785,40.048718,0.31938422,96.154397,361.9234,2.855,1,,,,5.9956173E-5,115.44184,3826.2264,1.125135,0
33778359.77,,5905,64.2982,64.3475,0.127,9.4E-6,64.092387,1.198961,72.510541,1.024,744.83876,0.8893,2476.594,1.932,0.47360325,41.242575,0.33972268,96.083725,367.04978,2.972,1,,,,6.125632E-5,118.66044,4107.834,1.1313441,0
33779698.02,,5905,66.5191,66.5653,0.127,9.4E-6,66.316521,1.2370405,75.298247,1.063,799.94128,0.9238,2598.2747,1.851,0.60729006,42.13731,0.35361581,96.065452,372.19971,3.065,1,,,,6.2882343E-5,121.91214,4397.8809,1.1354372,0
33781058.45,,5905,68.7452,68.7913,0.127,9.3E-6,68.535672,1.276259,78.073918,1.103,856.70126,0.9558,2721.3255,2.022,0.49214351,43.248128,0.37707044,95.965049,377.11166,3.188,1,,,,6.41768E-5,124.7612,4697.1383,1.139172,0
33782442.47,,5905,70.9715,71.0082,0.127,9.4E-6,70.763642,1.3151482,80.547814,1.137,915.6072,0.987,2839.315,1.813,0.65305181,43.940964,0.38489256,96.001257,382.64088,3.27,1,,,,6.5863211E-5,127.93853,5007.493,1.1382655,0
33783849.81,,5905,73.1952,73.2156,0.127,9.4E-6,72.986066,1.3533964,83.175149,1.174,976.4397,1.018,2962.8957,1.828,0.83580524,44.813401,0.40271269,95.946647,387.49433,3.38,1,,,,6.7383396E-5,130.82811,5326.9658,1.1396031,0
33785280.58,,5905,75.4194,75.4757,0.127,9.4E-6,75.219577,1.3953521,85.864799,1.212,1039.7424,1.048,3090.4348,2.045,0.53824216,45.969038,0.4276987,95.850114,392.00615,3.514,1,,,,6.8522506E-5,133.7704,5657.9848,1.141522,0
33786737.77,,5905,77.6426,77.6748,0.127,9.4E-6,77.437904,1.433553,88.199214,1.245,1104.6506,1.076,3211.0953,1.888,0.9017981,46.651412,0.43859499,95.855112,397.1693,3.607,1,,,,7.0124867E-5,136.48762,5996.629,1.138967,0
33788214.13,,5905,79.8667,79.9056,0.127,9.3E-6,79.670932,1.4745276,90.688462,1.28,1172.098,1.104,3337.993,2.042,0.59792828,47.609749,0.46047742,95.780325,401.76689,3.738,1,,,,7.1424942E-5,139.26027,6347.4575,1.1382879,0
33789709.64,,5905,82.0925,82.1275,0.127,9.3E-6,81.887588,1.5150262,92.970003,1.312,1241.2623,1.134,3461.6469,2.032,0.53373848,48.435065,0.48210698,95.702237,406.62905,3.85,1,,,,7.2803864E-5,142.06787,6705.5771,1.1353369,0
33791178.66,,5905,84.3157,84.3585,0.127,9.3E-6,84.124418,1.5524659,95.444927,1.348,1313.4117,1.171,3592.9044,2.232,0.36821605,49.365802,0.50055781,95.66196,410.84697,3.991,1,,,,7.4123597E-5,144.16791,7076.9177,1.1345686,0
33792718.06,,5905,86.5397,86.5831,0.127,9.3E-6,86.342702,1.5920015,97.901412,1.382,1387.4922,1.216,3725.6526,2.205,0.7792838,50.163936,0.51853073,95.615477,414.80916,4.107,1,,,,7.5625184E-5,147.10292,7455.0622,1.1338701,0
33794280.23,,5905,88.7662,88.8192,0.127,9.4E-6,88.581597,1.6314347,100.30267,1.416,1464.4988,1.265,3860.0081,2.226,0.63883908,51.033142,0.54149643,95.536656,418.81033,4.23,1,,,,7.7013106E-5,149.68773,7846.6994,1.1323195,0
33795861,,5905,90.9919,91.0356,0.127,9.3E-6,90.802274,1.6702,102.45252,1.446,1542.6381,1.309,3989.4918,2.337,0.52016737,51.725124,0.55705997,95.506323,423.22045,4.365,1,,,,7.8508942E-5,152.11396,8245.0529,1.1283035,0
33797459.06,,5905,93.2107,93.2688,0.127,9.3E-6,93.039351,1.7092723,104.7052,1.479,1622.6829,1.339,4123.3369,2.533,0.37709506,52.546843,0.57943491,95.432358,427.21756,4.513,1,,,,7.9866781E-5,154.38998,8656.3208,1.1253862,0
33799078.42,,5905,95.441,95.4809,0.127,9.3E-6,95.25911,1.7466201,107.05861,1.511,1703.7156,1.349,4260.5755,2.471,0.70920221,53.32218,0.59669329,95.39381,430.6468,4.632,1,,,,8.1308007E-5,156.46561,9074.298,1.1238674,0
33800713.95,,5905,97.6658,97.7178,0.127,9.3E-6,97.496713,1.7894911,109.15274,1.541,1787.0312,1.347,4393.9048,2.542,0.47574648,54.028038,0.61040764,95.378749,434.69755,4.765,1,,,,8.2729512E-5,158.95711,9505.6091,1.119553,0
33802362.73,,5905,99.8904,99.9447,0.127,9.4E-6,99.725639,1.8248597,111.37158,1.572,1871.4453,1.343,4531.3113,2.622,0.41107361,54.695357,0.63342429,95.289749,438.15963,4.908,1,,,,8.4274234E-5,161.0704,9945.203,1.1167799,0
33804029.52,,5905,102.118,102.158,0.127,9.3E-6,101.94327,1.8648679,113.3307,1.6,1956.5515,1.35,4663.2068,2.588,0.51622966,55.343809,0.65484007,95.213984,442.13425,5.033,1,,,,8.5703124E-5,163.23568,10392.431,1.1117036,0
33805714.61,,5905,104.346,104.396,0.127,9.4E-6,104.18308,1.9047288,115.40765,1.629,2043.4276,1.378,4799.6862,2.589,0.50550045,56.007285,0.67312111,95.161872,445.67554,5.174,1,,,,8.7152114E-5,165.2718,10854.114,1.1077389,0
33807410.59,,5905,106.561,106.613,0.127,9.4E-6,106.40344,1.9430563,117.29542,1.655,2130.6578,1.423,4932.0017,2.521,0.70828777,56.584083,0.68959805,95.116062,449.50391,5.293,1,,,,8.8624349E-5,167.25662,11321.692,1.1023649,0
33809121.72,,5905,108.792,108.848,0.127,9.4E-6,108.64749,1.9832751,119.25869,1.684,2220.0521,1.479,5068.2842,2.925,0.34148398,57.270006,0.71521844,95.016378,453.03477,5.481,1,,,,8.9982827E-5,169.10766,11804.276,1.0976663,0
33810852.13,,5905,111.002,111.079,0.127,9.4E-6,110.87743,2.0207679,121.33253,1.713,2309.9313,1.54,5207.6925,2.892,0.55660817,57.847838,0.73008383,94.980864,455.99065,5.618,1,,,,9.1516063E-5,170.91774,12293.804,1.0942942,0
33812592.5,,5905,113.239,113.292,0.127,9.4E-6,113.10079,2.0624896,123.13841,1.739,2400.6419,1.598,5341.5326,2.873,0.4565738,58.403718,0.74769005,94.926175,459.5578,5.755,1,,,,9.2960152E-5,172.71295,12791.789,1.0887493,0
33814349.25,,5905,115.463,115.523,0.127,9.4E-6,115.32896,2.0990022,125.67899,1.774,2492.7292,1.647,5494.2961,2.78,0.59878418,59.17622,0.78911214,94.730387,460.6985,5.896,1,,,,9.4408979E-5,174.53229,13300.77,1.0897435,0
33816056.08,,5905,117.696,117.744,0.127,9.3E-6,117.56672,2.1363056,126.9783,1.793,2586.6006,1.691,5619.1988,3.182,0.25401108,59.370708,0.7710944,94.880347,465.55025,6.086,1,,,,9.6153334E-5,175.8265,13821.934,1.0800531,0
33817773.95,,5905,119.91,119.953,0.127,9.4E-6,119.77299,2.1757475,128.77847,1.818,2680.6401,1.732,5756.2314,2.92,0.45967983,59.950453,0.79153591,94.808538,468.55885,6.196,1,,,,9.7537844E-5,177.52207,14345.568,1.075188,0
33819504.16,,5905,122.138,122.214,0.127,9.3E-6,122.02439,2.2051258,131.34596,1.854,2777.5419,1.772,5914.452,3.1,0.91267909,60.618944,0.83432934,94.600922,469.12352,6.385,1,,,,9.9156349E-5,178.17374,14889.951,1.076391,0
33821309.33,,5905,124.376,124.432,0.127,9.3E-6,124.25436,2.2476698,133.10185,1.88,2873.9866,1.81,6052.8322,3.227,0.84181903,61.228463,0.8551411,94.532709,472.00841,6.554,1,,,,0.00010045616,179.98003,15439.147,1.0712046,0
33823059.22,,5905,126.587,126.633,0.127,9.3E-6,126.46579,2.2867351,134.59753,1.9,2969.7043,1.848,6184.271,3.161,0.68085766,61.593552,0.87004257,94.480642,475.50952,6.693,1,,,,0.00010201237,181.31632,15993.595,1.0643,0
33824886.98,,5905,128.806,128.881,0.127,9.3E-6,128.71936,2.3245226,136.12926,1.922,3066.9147,1.886,6318.0633,3.273,0.40883981,61.691721,0.87183701,94.485376,478.90562,6.861,1,,,,0.00010401928,183.11353,16568.672,1.0575663,0
33826723.13,,5905,131.028,131.083,0.127,9.4E-6,130.93013,2.3629049,137.4484,1.943,3162.6551,1.923,6445.3086,3.867,0.43885129,61.82518,0.85233484,94.622989,482.70655,7.093,1,,,,0.00010580904,184.40565,17142.698,1.0497844,0
33828568.03,,5905,133.255,133.326,0.127,9.4E-6,133.17856,2.4048714,139.61937,1.971,3260.4518,1.961,6594.9542,3.329,0.31007893,62.502223,0.90702197,94.350977,483.63508,7.19,1,,,,0.00010715471,186.27282,17736.528,1.0483623,0
33830427.02,,5905,135.487,135.554,0.127,9.3E-6,135.41148,2.445941,140.91473,1.991,3357.8583,1.998,6723.2976,3.84,0.29374753,62.945501,0.93867053,94.203469,487.30422,7.417,1,,,,0.00010848352,187.16607,18336.269,1.040641,0
33832289.05,,5905,137.706,137.78,0.127,9.3E-6,137.63489,2.4808536,142.82201,2.017,3454.855,2.033,6865.8453,3.574,0.36623367,63.331486,0.96306724,94.094741,488.69515,7.551,1,,,,0.00011011686,188.01929,18943.364,1.0376875,0
33834166.2,,5905,139.936,139.976,0.127,9.4E-6,139.84485,2.5210865,144.3512,2.04,3551.1542,2.065,6998.6659,3.858,0.35872633,63.53485,0.96569532,94.09947,491.18477,7.757,1,,,,0.00011185709,189.44103,19556.582,1.0322239,0
33836046.69,,5905,142.152,142.226,0.127,9.4E-6,142.10119,2.5603861,145.66199,2.058,3649.4075,2.095,7128.2246,3.879,1.1879344,63.75071,0.98786237,93.989137,494.46264,7.923,1,,,,0.00011354443,190.71498,20192.749,1.0250582,0
33837938.98,,5905,144.376,144.451,0.127,9.3E-6,144.32359,2.5873574,148.06924,2.091,3746.3746,2.12,7282.6835,3.518,1.0115455,64.077654,0.99743249,93.962977,493.57104,8.067,1,,,,0.00011540342,190.68627,20829.297,1.0259532,0
33839764.08,,5905,146.607,146.65,0.127,9.4E-6,146.53538,2.6332441,149.07813,2.105,3843.1201,2.14,7403.524,3.55,0.20295794,64.220057,0.98283941,94.061121,497.4809,8.228,1,,,,0.00011699362,192.37106,21472.617,1.0173525,0
33841594.58,,5905,148.834,148.911,0.127,9.4E-6,148.79051,2.666813,150.32636,2.122,3941.7921,2.158,7532.0074,3.394,0.57697212,64.271929,0.9790107,94.086975,500.55853,8.373,1,,,,0.00011888931,192.48995,22138.617,1.0103222,0
33843497.8,,5905,151.056,151.126,0.127,9.4E-6,151.0149,2.6986983,153.03948,2.161,4039.1901,2.174,7694.2023,3.553,1.1163841,64.919211,1.0432647,93.771668,497.98539,8.62,1,,,,0.00012032552,193.00004,22805.499,1.0134065,0
33845340.05,,5905,153.285,153.314,0.127,9.4E-6,153.22015,2.7404762,153.42042,2.165,4135.1734,2.192,7799.2835,3.272,1.4865711,64.753634,1.0402606,93.770643,503.82937,8.715,1,,,,0.00012224078,194.2777,23476.414,1.0013071,0
33847249.72,,5905,155.501,155.563,0.127,9.3E-6,155.46902,2.7703732,155.14514,2.191,4232.6131,2.214,7937.9145,3.734,0.61304757,65.052537,1.0806324,93.563586,504.67682,8.984,1,,,,0.00012388351,193.87022,24170.615,0.99791681,0
33849165.25,,5905,157.723,157.801,0.127,9.3E-6,157.69759,2.8000202,156.81446,2.214,4328.2661,2.242,8073.4354,3.608,0.740246,65.026552,1.0463855,93.755557,505.50235,9.16,1,,,,0.00012596498,193.89189,24868.529,0.99439986,0
33851088.59,,5905,159.942,160.009,0.127,9.4E-6,159.92754,2.8486459,157.76299,2.227,4423.2126,2.277,8191.0355,3.482,0.64774733,65.437794,1.1014333,93.474291,508.9652,9.309,1,,,,0.00012705405,194.9403,25576.817,0.98646546,0
33853008.73,,5905,162.176,162.205,0.127,9.4E-6,162.12587,2.8827499,159.32932,2.249,4516.0858,2.319,8321.317,3.444,27.015751,65.661599,1.1333504,93.310737,509.80341,9.499,1,,,,0.00012866402,195.01303,26284.798,0.98275073,0
33854930.14,,5905,164.419,164.453,0.127,9.3E-6,164.38632,2.9152809,160.34737,2.264,4610.8884,2.367,8440.4335,3.831,0.49139387,65.603166,1.1386571,93.269587,512.86015,9.743,1,,,,0.00013060441,195.00096,27022.862,0.97543013,0
33856786.52,,5905,166.634,166.689,0.127,9.3E-6,166.62411,2.9534256,162.49999,2.295,4704.243,2.416,8585.1987,4.171,0.8394997,65.838924,1.1500917,93.225314,511.17503,10.04,1,,,,0.00013236839,195.83786,27763.596,0.97524892,0
33858715.36,,5905,168.854,168.88,0.127,9.4E-6,168.82151,2.9899363,162.88339,2.299,4795.4924,2.466,8685.6048,3.672,2.0041996,65.670595,1.1214211,93.364183,516.35436,10.1,1,,,,0.0001341791,195.62975,28500.703,0.96482603,0
33860642.97,,5905,171.076,171.109,0.127,9.4E-6,171.05168,3.0230962,164.66776,2.325,4887.9003,2.515,8820.6285,3.833,0.73124629,65.738156,1.1613657,93.139997,515.8172,10.36,1,,,,0.00013617862,196.1148,29258.677,0.96267843,0
33862430.27,,5905,173.304,173.365,0.127,9.3E-6,173.31405,3.0531645,166.00922,2.345,4981.5104,2.562,8946.2765,4.374,0.26863632,65.80898,1.1804731,93.033247,517.04105,10.66,1,,,,0.00013797958,195.48833,30037.759,0.9578521,0
33864217.91,,5905,175.53,175.602,0.127,9.4E-6,175.53536,3.0817322,167.51377,2.365,5073.4127,2.602,9074.1116,4.03,21.799929,66.033879,1.2384143,92.724434,517.31342,10.82,1,,,,0.00013955261,194.40109,30812.661,0.95430217,0
33866081.95,,5905,177.753,177.777,0.127,9.4E-6,177.74331,3.1254841,167.98203,2.371,5164.2631,2.633,9176.1454,3.768,0.69224422,65.60318,1.1756207,93.025773,521.81871,10.94,1,,,,0.0001419151,195.89211,31592.683,0.9450822,0
33868013.86,,5905,179.979,180.006,0.127,9.4E-6,179.97623,3.1546235,169.4842,2.394,5256.0531,2.653,9303.8114,4.352,0.50617306,65.587557,1.2197364,92.768032,521.87417,11.27,1,,,,0.00014398674,195.61721,32391.442,0.94170327,0
33869942.98,,5905,182.21,182.261,0.127,9.4E-6,182.24027,3.1972341,171.00694,2.415,5348.8542,2.666,9432.9799,4.192,0.45282698,65.674721,1.2194597,92.772954,521.76911,11.48,1,,,,0.00014576955,196.43611,33211.515,0.93835981,0
33871873.2,,5905,184.43,184.486,0.127,9.4E-6,184.46801,3.2204211,171.92022,2.427,5439.8153,2.676,9545.7526,3.756,0.40477351,65.265011,1.1670958,93.02052,524.09806,11.6,1,,,,0.0001483293,195.48402,34028.445,0.93197854,0
33873724.97,,5905,186.649,186.683,0.127,9.3E-6,186.66785,3.2491757,172.67495,2.439,5529.5103,2.688,9653.4726,4.412,0.35723295,65.042919,1.2244413,92.659872,526.96164,11.92,1,,,,0.00015060439,195.26568,34844.885,0.92503852,0
33875505.17,,5905,188.871,188.896,0.127,9.4E-6,188.88899,3.2875856,174.68635,2.467,5620.0834,2.705,9792.0835,4.459,0.80035344,65.471304,1.25516,92.527398,524.09606,12.21,1,,,,0.00015179911,194.89281,35679.05,0.92480958,0
33877429.72,,5905,191.102,191.168,0.127,9.4E-6,191.1563,3.3291555,174.79049,2.468,5712.2751,2.734,9886.7624,4.102,0.50514986,65.13709,1.2345591,92.595365,529.90811,12.29,1,,,,0.00015399024,195.25684,36540.73,0.91438519,0
33879350.92,,5905,193.315,193.371,0.127,9.3E-6,193.38473,3.3662863,176.19724,2.487,5802.9404,2.778,10011.025,3.953,0.61112595,65.156308,1.2450774,92.53049,529.53877,12.51,1,,,,0.00015588111,195.22934,37397.655,0.91112282,0
33881128.14,,5905,195.561,195.58,0.127,9.4E-6,195.60609,3.3928225,177.2722,2.502,5893.446,2.841,10127.204,4.009,2.7837604,65.295354,1.2994511,92.22714,530.55726,12.75,1,,,,0.00015743004,193.65123,38261.744,0.90627137,0
33882974.39,,5905,197.774,197.779,0.127,9.3E-6,197.80813,3.4302502,178.62547,2.522,5983.4748,2.93,10249.552,4.164,27.438269,65.13414,1.2985422,92.206688,530.07664,13.04,1,,,,0.00015971237,194.2738,39128.056,0.9030239,0
33884885.25,,5905,200.007,200.044,0.127,9.4E-6,200.07212,3.4602918,179.28455,2.534,6076.6747,3.052,10358.493,4.99,0.59884297,64.704685,1.2970006,92.154465,532.96157,13.42,1,,,,0.00016246591,194.19466,40028.853,0.89609963,0
33886790.69,,5905,202.003,202.041,0.127,9.4E-6,202.07338,3.4921967,180.05362,2.541,6159.4745,3.179,10459.66,3.962,7.1763728,64.676323,1.2879476,92.193555,534.53961,13.4,1,,,,0.00016408544,193.55493,40833.651,0.8910309,0
33888508.75,,5905,202.994,203.047,0.127,9.3E-6,203.08139,3.488108,180.09823,2.543,6201.1676,3.248,10502.419,4.193,0.48324909,64.151649,1.2278736,92.475322,536.98721,13.52,1,,,,0.00016599096,191.68682,41242.05,0.88682785,0
33890286.2,,5905,203.992,204.036,0.127,9.4E-6,204.08945,3.5148286,180.26251,2.545,6242.9036,3.319,10548.078,4.351,0.70266714,64.217752,1.2812781,92.165867,538.84262,13.64,1,,,,0.00016662872,192.44282,41652.506,0.88325242,0
33892068.81,,5905,205.009,205.051,0.127,9.3E-6,205.08479,3.5222188,181.35781,2.563,6284.2092,3.39,10615.542,4.901,1.0016771,64.446684,1.334717,91.883144,536.03845,13.92,1,,,,0.00016719266,191.57455,42059.769,0.88430648,0
33893844.86,,5905,205.995,206.039,0.127,9.4E-6,206.08546,3.5362081,181.52591,2.564,6325.5312,3.463,10660.879,4.537,0.3877679,64.232982,1.3193348,91.940042,537.81547,13.93,1,,,,0.00016842943,191.31917,42471.217,0.88082833,0
33895621.84,,5905,206.988,207.036,0.127,9.3E-6,207.08714,3.5621353,181.78736,2.566,6366.7276,3.535,10708.32,4.077,6.7550555,64.218026,1.3437293,91.791157,539.11876,13.92,1,,,,0.00016925396,192.36566,42885.083,0.87783028,0
33897396.52,,5905,208.019,208.029,0.127,9.3E-6,208.08387,3.5633035,182.75494,2.581,6407.6165,3.606,10772.317,4.603,1.8606968,64.110001,1.3130184,91.954837,536.83493,14.19,1,,,,0.0001704933,191.08134,43298.896,0.8782754,0
33899241.2,,5905,209.008,209.054,0.127,9.3E-6,209.08432,3.588578,182.58078,2.579,6448.4408,3.676,10808.982,4.623,2.5752376,64.033257,1.3398797,91.780882,540.29888,14.25,1,,,,0.00017131617,191.60694,43716.252,0.87323996,0
33901084.28,,5905,210,210.05,0.127,9.4E-6,210.07773,3.5914886,183.47776,2.591,6488.8662,3.744,10870.83,4.612,5.1855927,63.961591,1.3419361,91.758559,538.29465,14.4,1,,,,0.00017249303,190.54641,44132.655,0.87338032,0
33902922.2,,5905,211.017,211.046,0.127,9.4E-6,211.08569,3.6142755,183.16935,2.588,6529.5932,3.809,10904.191,4.837,1.1774112,63.780104,1.3344715,91.76994,542.45745,14.49,1,,,,0.00017348668,191.06016,44557.168,0.86774878,0
33904757.75,,5905,211.996,212.066,0.127,9.3E-6,212.0836,3.6268688,184.12675,2.604,6569.7682,3.87,10967.232,5.595,1.518759,64.014074,1.4107939,91.354806,540.09103,14.82,1,,,,0.0001739916,190.34886,44979.452,0.86818008,0
33906526.44,,5905,212.998,213.024,0.127,9.3E-6,213.04432,3.6371217,184.3026,2.604,6608.099,3.925,11009.762,5.045,0.86949912,63.843216,1.3769102,91.52319,541.62696,14.79,1,,,,0.00017506009,189.56732,45387.881,0.86509041,0
33908358.58,,5905,214.002,214.008,0.127,9.3E-6,214.04245,3.6505827,184.78653,2.612,6647.5613,3.977,11060.782,5.296,1.3157901,63.671494,1.3885495,91.429396,541.64516,14.96,1,,,,0.00017636751,189.86534,45814.173,0.86331721,0
33910122.28,,5905,214.998,215.005,0.127,9.4E-6,215.04225,3.6624923,184.62369,2.609,6686.6721,4.023,11096.004,4.985,1.1284386,63.328471,1.3538803,91.57971,545.02717,14.95,1,,,,0.00017781388,189.54683,46243.17,0.85854612,0
33911946.41,,5905,215.999,215.991,0.127,9.4E-6,216.04464,3.6802805,185.07833,2.615,6725.6222,4.062,11145.812,4.964,3.0469353,63.330326,1.3651255,91.509383,545.17738,15.06,1,,,,0.00017862053,189.35864,46675.287,0.85666709,0
33913636.3,,5905,217.004,217.059,0.127,9.4E-6,217.0778,3.6880571,186.17642,2.633,6765.4466,4.096,11211.862,5.742,1.1948345,63.508689,1.4287569,91.160411,541.97478,15.43,1,,,,0.00017929592,188.37054,47122.769,0.85764836,0
33915465.14,,5905,218,218.066,0.127,9.4E-6,218.08511,3.7119834,186.05649,2.632,6803.5533,4.12,11247.104,5.97,0.65890045,63.125748,1.3886725,91.336219,545.1278,15.54,1,,,,0.00018086811,189.38194,47561.115,0.85313706,0
33917288.88,,5905,218.999,219.05,0.127,9.4E-6,219.08245,3.7254608,186.75498,2.64,6841.1875,4.135,11301.421,5.263,1.7785919,63.126776,1.3927106,91.310103,543.88511,15.53,1,,,,0.00018174194,189.1251,47997.12,0.85244155,0
33919039.08,,5905,219.997,220.04,0.127,9.3E-6,220.0867,3.7379555,187.43669,2.651,6878.7613,4.143,11355.275,5.849,3.7094994,63.224036,1.4514192,90.976275,542.71015,15.81,1,,,,0.00018243846,188.35605,48438.157,0.85164933,0
33920793.08,,5905,220.98,221.033,0.127,9.4E-6,221.09108,3.7555219,188.12493,2.659,6915.9409,4.144,11408.892,5.249,1.3742245,63.008471,1.3799579,91.364766,541.46092,15.83,1,,,,0.00018378361,188.69067,48881.265,0.85089335,0
33922607.94,,5905,221.996,222.046,0.127,9.4E-6,222.08822,3.7665699,188.15093,2.658,6952.5892,4.138,11446.161,5.012,1.3544609,62.741144,1.3822718,91.308947,543.76146,15.85,1,,,,0.00018517218,188.40263,49323.178,0.84719004,0
33924353.66,,5905,223.003,223.045,0.127,9.4E-6,223.09235,3.7875797,188.49793,2.665,6989.4428,4.126,11491.302,5.609,1.1888039,62.89358,1.4325636,91.027132,544.32196,16.1,1,,,,0.00018553991,188.13053,49770.198,0.84493228,0
33926098.86,,5905,224.005,224.01,0.127,9.3E-6,224.04517,3.7937898,189.80782,2.684,7024.0092,4.11,11557.153,5.573,14.101977,62.85672,1.4458135,90.947233,539.43638,16.32,1,,,,0.0001867481,187.66125,50196.24,0.8471855,0
33927906.22,,5905,225.001,225.007,0.127,9.3E-6,225.04483,3.803979,189.55829,2.678,7060.0341,4.089,11587.218,4.988,27.514966,62.539211,1.4129777,91.088598,543.22483,16.23,1,,,,0.00018811119,186.90367,50645.175,0.84231348,0
33929579.34,,5905,226.001,226.015,0.127,9.4E-6,226.03753,3.8052302,190.83211,2.697,7095.5021,4.065,11653.108,5.415,2.535138,62.35258,1.3927314,91.186501,538.52733,16.57,1,,,,0.00018971775,186.21891,51092.963,0.84424969,0
33931380.86,,5905,226.996,226.998,0.127,9.3E-6,227.04183,3.8306768,191.18281,2.701,7131.2563,4.037,11697.238,5.122,7.9127182,62.268904,1.4241745,90.983346,538.95392,16.62,1,,,,0.00019075444,187.00547,51547.992,0.84205985,0
33933043.39,,5905,228.001,228.04,0.127,9.4E-6,228.07447,3.8333162,191.67253,2.71,7167.7725,4.006,11745.45,5.567,2.6529228,62.220784,1.3963446,91.138675,538.64379,16.87,1,,,,0.00019162345,185.22559,52017.966,0.84039448,0
33934774.67,,5905,229.006,229.056,0.127,9.3E-6,229.07477,3.8542908,191.86699,2.711,7202.8722,3.975,11785.194,5.155,2.5612809,61.998944,1.4039106,91.057611,539.90374,16.87,1,,,,0.00019297562,185.86725,52475.251,0.83757364,0
33936570.61,,5905,229.995,230.065,0.127,9.3E-6,230.07905,3.8727634,191.84907,2.712,7237.954,3.942,11819.848,5.564,0.87004173,62.004189,1.4499398,90.775528,542.37281,17.04,1,,,,0.00019361157,185.49294,52936.369,0.83383979,0
33938296.23,,5905,231.013,231.05,0.127,9.3E-6,231.06148,3.8849395,192.2615,2.717,7272.1029,3.91,11863.847,5.213,10.872602,61.965139,1.4551247,90.73499,542.32819,17.08,1,,,,0.00019446013,184.798,53389.41,0.83207939,0
33940062.91,,5905,233.051,233.057,0.127,9.3E-6,233.08188,3.8996362,193.07779,2.732,7341.4159,3.846,11952.655,6.325,0.88682405,61.353272,1.4254352,90.818798,542.34837,17.62,1,,,,0.00019781902,184.27422,54327.161,0.82836895,0
33941820.36,,5905,235.069,235.092,0.127,9.3E-6,235.11093,3.9112229,195.28221,2.765,7410.3953,3.789,12074.282,6.841,2.2619699,60.936588,1.2956188,91.555973,534.14165,18.24,1,,,,0.00020093171,182.8673,55277.149,0.83059604,0
33943567.73,,5905,237.087,237.127,0.127,9.3E-6,237.14436,3.9705466,192.75775,2.723,7478.9701,3.745,12082.566,4.884,3.0587093,60.917352,1.389826,90.940173,553.68628,17.52,1,,,,0.0002012801,182.28831,56237.45,0.81282871,0
33945375.03,,5905,239.115,239.148,0.127,9.4E-6,239.17681,4.0019979,193.25239,2.731,7546.7767,3.72,12162.186,5.417,0.79650869,60.654595,1.4003944,90.827344,555.49233,17.88,1,,,,0.00020350171,181.75056,57205.546,0.80798968,0
33947046.42,,5905,241.146,241.174,0.127,9.4E-6,241.20119,4.0177302,192.64041,2.723,7613.6975,3.72,12214.491,5.556,0.33415941,60.133599,1.3813756,90.849281,563.86062,17.97,1,,,,0.00020609457,179.60496,58178.012,0.79867108,0
33948709.7,,5905,243.178,243.206,0.127,9.3E-6,243.24302,4.0540882,193.36403,2.733,7680.671,3.751,12298.747,5.46,0.66323928,60.06778,1.4332989,90.509028,564.26081,18.21,1,,,,0.00020785014,179.17917,59167.165,0.79494177,0
33950366.75,,5905,245.21,245.188,0.127,9.4E-6,245.23814,4.0778139,193.87507,2.738,7745.4729,3.808,12375.754,4.822,4.949183,59.682671,1.4206701,90.519572,565.76898,18.27,1,,,,0.00021047456,178.31665,60141.744,0.7905584,0
33952081.06,,5905,247.238,247.226,0.127,9.4E-6,247.27624,4.1054878,193.92883,2.74,7810.9472,3.891,12442.512,5.067,1.5431927,59.223489,1.41861,90.448236,570.13966,18.5,1,,,,0.00021324504,177.74698,61145.538,0.78425986,0
33953788.05,,5905,249.254,249.307,0.127,9.4E-6,249.34807,4.1323299,195.28464,2.762,7877.0091,3.995,12540.954,5.946,0.73772045,59.229989,1.4750228,90.092984,566.47145,19.11,1,,,,0.00021503697,176.73721,62174.462,0.78318084,0
33955491.05,,5905,251.287,251.333,0.127,9.3E-6,251.38369,4.1698918,194.76312,2.753,7941.1071,4.112,12592.597,5.594,1.4765745,58.829475,1.4727516,90.022591,574.37586,19.08,1,,,,0.00021737393,176.3404,63193.761,0.77476433,0
33957186.8,,5905,253.308,253.37,0.127,9.3E-6,253.42003,4.1977891,195.2926,2.762,8004.5309,4.239,12668.666,6.072,1.3150941,58.634096,1.5284745,89.629606,575.67163,19.46,1,,,,0.0002195438,175.58051,64221.713,0.7706281,0
33958812.5,,5905,255.322,255.391,0.127,9.3E-6,255.44778,4.2109371,195.78938,2.768,8066.7605,4.37,12742.76,5.67,1.2975747,58.121314,1.4799563,89.841822,577.09704,19.59,1,,,,0.00022267081,173.70663,65253.57,0.76645557,0
33960428.94,,5905,257.383,257.368,0.127,9.4E-6,257.43802,4.2368127,196.30209,2.775,8127.193,4.501,12815.438,5.796,4.6914349,57.909007,1.5245289,89.512512,578.27848,19.87,1,,,,0.00022486838,172.76143,66274.333,0.76252176,0
33962106.22,,5905,259.412,259.403,0.127,9.3E-6,259.47853,4.2779236,196.08387,2.773,8188.21,4.63,12871.243,6.018,1.7418578,57.539753,1.5242288,89.432922,584.28489,20.05,1,,,,0.00022728866,172.81579,67329.108,0.75568436,0
33963714.19,,5905,261.44,261.424,0.127,9.3E-6,261.51017,4.2944024,196.45774,2.778,8248.0922,4.751,12940.054,5.78,2.1475268,57.074772,1.5246323,89.338457,586.40211,20.2,1,,,,0.00023037755,171.50957,68387.571,0.75124321,0
33965309.8,,5905,263.468,263.5,0.127,9.4E-6,263.58432,4.3178362,197.29361,2.793,8308.4576,4.86,13020.383,6.833,0.36571805,56.903977,1.5466071,89.159665,585.50187,20.82,1,,,,0.00023256012,170.13144,69476.691,0.74850286,0
33966900.36,,5905,265.506,265.518,0.127,9.4E-6,265.62068,4.3419876,197.74083,2.799,8366.6525,4.95,13089.258,6.75,0.48351279,56.5297,1.5633236,88.973696,587.0244,21.04,1,,,,0.00023539005,169.15077,70554.344,0.74444818,0
33968545.19,,5905,267.52,267.557,0.127,9.4E-6,267.65679,4.3707136,198.83786,2.817,8423.8443,5.017,13172.65,7.183,0.55296529,56.307252,1.6135395,88.604112,584.08226,21.55,1,,,,0.00023797019,168.81329,71640.157,0.74288367,0
33970182.94,,5905,269.553,269.6,0.127,9.4E-6,269.69374,4.3964711,199.86205,2.828,8480.0774,5.057,13253.344,6.526,0.73624057,56.025847,1.595975,88.662326,581.49352,21.73,1,,,,0.00024059851,167.85115,72734.716,0.74107041,0
33971812.95,,5905,271.593,271.559,0.127,9.4E-6,271.68379,4.4199923,200.6275,2.839,8534.0998,5.077,13325.647,6.484,5.3262386,55.676958,1.6238848,88.407991,580.46663,22.04,1,,,,0.0002435202,167.12295,73812.083,0.73845958,0
33973438.55,,5905,273.628,273.578,0.127,9.3E-6,273.71575,4.4381904,202.23223,2.862,8588.2899,5.088,13418.163,6.657,1.9994072,55.343012,1.6394631,88.245713,573.51051,22.62,1,,,,0.00024676885,166.32553,74920.313,0.73884031,0
33975056.53,,5905,275.652,275.596,0.127,9.4E-6,275.7503,4.4645791,202.82809,2.871,8641.7742,5.088,13485.878,6.748,5.6686438,55.086279,1.6725372,87.969607,573.52324,22.95,1,,,,0.00024927123,165.33238,76038.227,0.73554986,0
33976670.75,,5905,277.673,277.682,0.127,9.4E-6,277.82756,4.4909494,205.35476,2.91,8695.4986,5.076,13599.946,7.576,1.6737263,55.015144,1.7049819,87.758455,559.52981,24.02,1,,,,0.00025183432,164.84307,77188.151,0.73914468,0
33978217.36,,5905,279.706,279.718,0.127,9.3E-6,279.85044,4.4989294,206.28815,2.923,8746.9496,5.055,13673.689,7.692,2.2230143,54.772541,1.7736535,87.255539,556.71762,24.49,1,,,,0.00025454028,162.76976,78316.271,0.73713711,0
33979764.13,,5905,281.73,281.72,0.127,9.4E-6,281.89119,4.5424188,207.38001,2.937,8797.7982,5.023,13750.615,7.43,6.0400903,54.601708,1.810188,86.979206,552.61078,24.89,1,,,,0.00025689709,163.14907,79462.641,0.73567396,0
33981305.94,,5905,283.778,283.752,0.127,9.4E-6,283.92738,4.5674216,208.62483,2.956,8847.7018,4.98,13830.248,7.762,2.3332703,54.257191,1.8026064,86.954894,547.15084,25.55,1,,,,0.00026003906,162.42158,80614.757,0.73478235,0
33982902.28,,5905,285.804,285.731,0.127,9.4E-6,285.91085,4.5972742,209.45533,2.965,8895.4247,4.928,13897.806,7.1,6.8394568,53.956846,1.8515014,86.563764,544.57676,25.77,1,,,,0.00026294031,162.14027,81745.017,0.73258965,0
33984481.08,,5905,287.819,287.755,0.127,9.3E-6,287.92548,4.5985009,210.52125,2.979,8943.1903,4.864,13971.028,6.867,107.05901,53.661703,1.8694365,86.378169,540.08858,26.22,1,,,,0.00026586737,159.61714,82901.084,0.73116575,0
33986063.61,,5905,289.858,289.781,0.127,9.4E-6,289.9802,4.6686362,210.36719,2.976,8990.7981,4.789,14014.957,6.545,12.102264,53.392537,1.8208087,86.621374,545.15892,26.25,1,,,,0.00026788697,160.94685,84088.519,0.72545362,0
33987579.72,,5905,291.878,291.851,0.127,9.3E-6,292.0529,4.6959942,209.46604,2.963,9038.0099,4.702,14040.647,6.64,5.4940278,53.10116,1.8581011,86.27944,556.19107,26.17,1,,,,0.00026994885,159.04799,85294.897,0.71721951,0
33989083.81,,5905,293.925,293.886,0.127,9.4E-6,294.08677,4.7266781,206.95446,2.928,9083.37,4.607,14026.023,6.656,1.5616633,52.365298,1.7599909,86.720346,579.84646,25.58,1,,,,0.00027312374,157.32526,86487.03,0.70371903,0
33990577,,5905,295.944,295.909,0.127,9.4E-6,296.12098,4.7527257,206.36004,2.917,9127.7841,4.5,14056.241,5.783,3.9397337,51.733764,1.6509221,87.307032,588.5222,25.29,1,,,,0.00027672272,156.05783,87687.632,0.6968775,0
33992114.91,,5905,297.97,297.939,0.127,9.3E-6,298.14889,4.7918426,206.28747,2.915,9171.3181,4.383,14098.042,5.533,2.9206686,51.535895,1.6308167,87.388866,593.1248,25.35,1,,,,0.00027853932,154.98643,88892.763,0.69189413,0
33993586.7,,5905,300.028,299.978,0.127,9.4E-6,300.16996,4.8013652,205.65737,2.906,9213.7668,4.257,14125.442,5.497,2.6139625,50.948182,1.5927831,87.504632,602.13624,25.33,1,,,,0.00028219529,152.88608,90102.008,0.68513641,0
33994346.69,,5905,299.99,299.959,0.127,9.3E-6,300.21673,4.8276819,204.73194,2.906,9214.7357,4.254,14104.309,8.645,0.037766911,50.529093,1.5162487,87.948584,609.52635,26.15,1,,,,0.00028387395,151.80765,90130.086,0.68194713,0